sample_out/43206830319845.txt
FMS 36.3
MTEC 10.14
JELD 16.72
FSZ 47.26
AMTD 55.5
RFP 9.18
YEXT 14.99
GMED 43.86
AUMN 0.337
ORMP 3.42
SFE 9.5
EVOP 25.05
TBBK 8.55
ESIO 29.995
USCI 38.77
RBS 6.43
CTG 4.28
AFMD 3.19
DRIP 10.85
JTD 14.97
VYM 81.7
CBZ 19.51
ECA 6.955
SBFGP 18.22
SPEM 34.54
UNG 25.62
FII 26.48
WCC 53.51
HDSN 1.21
ESL 121.52
BH.A 650.0
SDG 56.43
CTB 34.085
VET 24.14
VMI 126.57
IYJ 141.4
MBIO 3.35
VOX 78.24
XBIO 2.07
EMLP 23.35
DCP 33.42
MPAA 20.17
NVEC 93.55
JHSC 24.98
LMAT 23.83
RWM 42.61
ESNT 38.62
BGS 26.51
FICO 215.69
XELA 3.55
PERI 3.27
SPHD 40.75
TLC 6.5
HLIT 5.13
AMID 4.05
DK 32.06
VONV 103.64
HR 31.94
CACI 158.31
GNR 44.63
TBPH 24.43
DRW 30.71
WDAY 169.13
FENC 6.3
CCLP 2.53
AYX 69.61
MDC 30.34
UJPY 25.3
CBRE 44.56
GPP 15.38
AGM 70.75
BLX 18.64
ISIG 1.18
CACG 28.715
CNDT 12.52
MNTX 6.95
VTC 81.25
DGS 45.12
IAGG 52.48
GLL 70.1
MSC 13.4
OGS 80.52
EPAM 139.0
CIGI 61.48
MXWL 3.005
AGO 40.23
AMBR 8.31
OIBR.C 1.64
FUV 3.03
CRS 44.46
BIOS 3.57
QSR 62.11
AMRWW 0.11
UFPI 29.07
PHB 18.26
IUSB 49.54
NOG 2.53
GWR 78.73
CPA 94.09
OPTN 6.12
FDEU 14.0
GLV 10.69
QTWO 57.33
AAON 35.645
SKIS 4.6
CPT 96.6
PII 83.06
BSIG 12.4
DHIL 156.62
FSK 6.31
HPE 15.42
ATIS 0.3
REN 33.4
OZK 31.66
BTN 1.55
XLNX 110.49
GVAL 22.83
OLED 102.085
GSIT 7.87
PUMP 16.0
YINN 21.37
SCE-J 20.23
GNL-A 24.53
KMI 18.125
DG 115.315
SMDV 56.69
CPRT 49.91
QGEN 37.26
QARP 24.84
CLNC 16.42
RECN 16.56
GARS 7.39
CVA 15.7
URTH 83.85
USPH 106.15
ELF 8.44
ATHM 71.5
ERIC 8.855
CFFI 50.24
BPOPN 25.71
WVVI 7.06
MILN 21.66
VVV 22.43
BBRE 79.98
ANIP 53.56
XSW 82.8
RYTM 25.86
DIV 23.63
LMNR 21.68
INDB 79.18
PVTL 18.12
SPLV 48.97
CGIX 0.2464
ALNA 7.64
IMAX 20.94
DUK 85.96
RYB 7.07
CHEF 32.31
EEA 8.14
PSA-C 23.145
ARRS 31.285
CCS 21.68
BR 99.91
COHU 17.55
MGRC 49.63
ETJ 8.52
LECO 86.42
MDCA 2.98
CLIX 47.16
VDE 85.3
DPG 13.83
QYLD 21.75
ADSK 142.18
NYT 26.14
NSYS 4.18
PCG 13.66
PML 13.49
ORC 6.985
CBMB 12.78
CNS 37.165
CPE 8.18
FSCT 29.51
CAAP 6.99
HSC 21.15
CNXM 17.34
FATE 13.99
LCNB 16.41
LXFT 57.715
FOXA 49.025
WEYS 27.33
EFR 13.07
WATT 7.27
PBIP 18.25
ALB 79.3
ELLI 72.64
GEN 1.5
WSC 10.27
NFRA 46.6
JXI 50.61
CIG 3.705
DLPN 1.62
FRT 131.41
LEO 7.63
ALDR 12.77
UCBI 26.16
MFA-B 24.77
AQN 10.92
DSM 7.36
FNLC 26.15
WMC 9.58
CASY 128.475
PCMI 20.93
MOBL 4.75
BSTC 64.62
SSRM 13.33
INSI 18.5
AUTO 3.18
CCR 18.45
GDO 15.98
RDVT 7.5
ON 19.59
SON 56.72
AAME 2.53
USO 11.52
CYH 3.695
SP 32.72
VTVT 2.71
QHC 2.96
PSAU 18.4
KIM-L 21.39
EPE 0.6806
HEES 26.11
ISSC 2.08
DEUS 30.62
EV 38.07
CLNY-J 20.32
WFC-Q 25.39
IBDQ 24.2
BIP 38.39
HALO 16.03
IPAR 66.93
TOWR 29.1
ADOM 0.252
IPLDP 24.9
CPST 0.8501
TNK 1.01
GRC 33.15
VOOV 104.61
PSCI 60.84
WHLM 5.85
WNEB 9.36
PFFA 23.75
KONA 1.11
AMAG 15.22
AUPH 6.32
YLCO 12.21
DAVA 23.58
CC 35.63
PDFS 10.26
TISA 0.52
AYTU 1.12
FINX 24.79
YVR 2.35
UIS 12.88
TMO 241.97
YRCW 5.79
UWN 2.47
TPH 12.49
VERU 1.48
WMB 26.945
XHE 74.43
COWNZ 24.92
MTEX 18.86
ETP-D 24.63
CSU 7.19
HLNE 36.44
DJP 22.54
OXY 66.885
BDC 52.49
FMHI 50.23
CDR-B 24.46
MSA 96.72
DGII 11.49
SAIC 67.23
PMBC 7.94
CIZ 31.45
UPWK 18.87
ARTX 3.44
KALV 17.5
BAX 71.13
CCD 19.28
PRO 33.96
STNLW 0.85
FELP 3.35
ERJ 20.79
DDWM 27.52
EMCB 69.57
NCTY 1.31
MMT 5.56
TIF 87.37
BMI 51.75
TOUR 4.4
SLNO 1.72
SBLKZ 25.0
CCMP 100.17
XRX 27.94
VLGEA 26.67
XEL 50.94
LTPZ 62.57
XHR 18.57
ATHN 134.53
FOE 16.48
FPAY 0.799
DRAD 0.72
JMEI 2.59
TNXP 2.02
DRRX 0.5998
SSW-H 23.25
NIU 7.61
FTXD 21.54
BRSS 29.22
OSG 1.91
MGLN 66.07
XLU 53.47
NPTN 6.945
DNLI 18.59
DAIO 5.84
HYLB 48.65
REGL 54.68
IDEV 51.98
UMBF 63.07
SLYG 58.0
GRNQ 3.2
PPT 4.98
CHY 10.91
NOA 10.41
RWW 63.09
LENS 0.44
MDYV 49.21
DLS 64.35
HTLD 20.04
KNL 19.63
JLL 139.68
SBFG 18.4
NAVG 69.755
GSLC 53.38
KBE 43.07
C-N 26.28
RFEU 56.47
CRL 121.72
JILL 6.02
OHGI 0.1205
MXL 19.04
CERS 5.74
GLMD 7.17
DVD 1.99
CBD 25.96
HIL 3.33
EMO 9.5
HST 18.135
DVN 27.19
SPXU 38.37
AIMC 29.46
TRT 2.95
NEE 173.26
EOLS 15.44
FAN 12.58
CENX 8.815
RUBY 13.78
EDD 6.635
VHT 166.88
TNC 58.21
SALM 2.76
CHAP 7.83
LXFR 19.87
ORLY 344.77
RGR 53.32
WGP 32.77
DES 26.94
WSTL 2.19
GFI 4.04
EES 35.57
ALD 44.03
AMN 64.28
NEO 16.63
BDC-B 72.22
ALDX 8.44
WOR 36.56
TWOU 55.8
PFL 11.29
AGCO 63.51
MGA 52.17
BKK 14.93
CEI 0.4609
EPHE 34.21
AVAL 6.76
DWSH 25.9
AFIF 9.94
BPFH 11.69
ACRE 14.34
IYH 187.2
TEL 79.26
PRCP 8.0
DRN 22.55
SPOK 13.7
EDV 112.52
BWA 40.34
PAHC 31.12
SCOR 19.0
EXFO 3.29
VRSK 117.19
FLR 35.945
ALLT 6.73
EPR 72.47
HTY 6.87
CBH 8.77
ICLR 137.15
RFDI 55.28
EMN 81.85
CABO 865.55
MYJ 13.53
UAL 86.82
PRTA 11.72
SCHZ 50.825
LYV 52.67
AFSI-C 8.05
NPV 12.04
ARNC 18.59
VSEC 32.49
AME 72.04
KMT 37.68
PRTO 2.62
JG 7.71
BAH 48.34
MOXC 0.5201
MTUM 104.98
REGI 28.18
GLTR 64.92
FULT 16.26
PSJ 80.79
NUV 9.615
CI 196.92
ANH 4.475
ACER 23.42
CYTR 0.555
ATSG 23.59
JKE 168.63
ENB 36.5
IPHS 30.0
VIXM 24.26
FLWS 13.21
COPX 19.79
C-K 26.73
IESC 16.62
ATISW 0.08
APDN 0.46
VRTS 86.32
TCGP 22.51
SPXC 29.24
EVFM 3.48
INDL 57.95
PYPL 91.875
DCOM 19.73
EVA 30.13
FCBP 21.66
TDE 24.99
GRA 71.51
EPC 39.28
JAKK 1.88
ASTC 5.01
BSE 12.45
UG 19.44
DATA 126.42
FN 54.61
COUP 79.15
CTRN 20.62
DOG 57.36
ERF 8.83
ENT 2.6
GSBD 20.25
PDEX 14.89
FOLD 11.2
JAZZ 125.75
TRTX 19.59
SFST 36.94
TDW+A 2.22
BSCE 25.15
PZD 40.03
FTFT 0.79
ZG 32.59
SCO 20.05
HOFT 28.0
KGJI 0.77
LAD 88.3
NRT 6.25
SOLOW 0.4
KOP 23.01
KRC 70.35
TOTL 47.48
JDST 41.88
IGOV 48.9
CVLY 22.47
TTS 7.42
WBC 112.905
COWN 15.56
FTSV 14.6
MITT 17.88
RWR 95.12
CHMG 42.16
GASL 8.17
RJI 5.24
TENB 26.99
AIHS 4.0
MSI 116.64
MARPS 2.05
IPG 22.75
JPI 21.83
MSCI 161.93
RNR 138.17
ETON 6.19
FEX 56.34
MS-K 25.44
PLND 17.14
HSDT 7.26
MLM 179.74
SRV 9.88
TRI 51.63
STND 31.2
HUBG 44.23
EDRY 7.92
LLL 197.93
IYF 115.83
EXTR 7.46
CORT 11.54
NSP 103.99
GLP 19.13
CHSCP 28.97
BGIO 8.72
ENOB 6.1
SNY 42.685
PHCF 5.05
DFFN 2.16
SEND 49.2
CCOI 46.93
MIDU 36.38
KNX 32.73
TAIT 1.96
MODN 14.21
KMB 108.87
HYHG 65.07
APM 12.21
OKTA 78.25
HYLS 46.78
ARTNA 34.69
IGSB 52.08
FIF 14.96
LOGI 35.82
RETA 75.5
ECOL 62.6
MPB 23.99
CTL 14.93
ALTY 14.46
MBOT 8.59
FDUSL 25.3
TVTY 21.74
BFR 13.38
ATOM 3.94
NOC 278.7
VTSI 3.99
SBUX 67.47
FMAO 31.08
FET 4.86
EWH 24.29
NTRS 89.25
SDIV 19.04
SONO 11.11
CHN 18.87
VLRS 7.48
SLY 65.3
STL 19.38
AGYS 17.64
FAM 9.86
NCLH 50.1
ULH 20.415
ALG 86.34
NNVC 0.31
THRM 40.72
BAF 13.29
UTSL 27.14
BH 131.2
EDZ 47.4
GLW 33.48
WWE 82.04
MORT 23.06
TRK 16.21
FCNCA 411.57
PAYC 143.31
TRGP 43.395
SBNY 126.41
CWK 16.15
ET 14.65
TYD 42.81
EARS 0.431
FREL 24.73
FNY 40.18
SPG 181.74
SNN 37.75
RHI 64.05
NBN 20.13
SSNC 50.145
CNP-B 52.76
THFF 41.53
IYR 82.65
COR 97.68
INFU 3.75
NGVC 13.33
NEWTI 25.56
AGRX 0.8449
BB 8.065
FSM 3.79
VGZ 0.66
HWKN 41.64
PB 71.9
AOS 47.24
SRTY 29.57
MOSY 0.18
IBDR 23.55
VRRM 10.28
IAI 60.57
OPNT 14.7
LUV 57.51
POOL 150.05
APPN 31.59
REV 24.78
EYES 0.82
AEO 21.15
MEIP 2.7
CFBI 10.68
TYME 2.73
NOMD 17.99
NWE 62.61
BIF 10.61
DPST 47.2
BHVN 38.5
ROAN 10.83
DFS 67.47
BCS 8.46
KSA 32.02
PSA-E 22.17
OSMT 7.92
MYE 16.15
SAR 23.0
LOGC 8.54
AMRX 12.03
SELF 3.99
AGR 49.0
GMLP 13.13
SLIM 32.5
BOCH 11.02
OPINI 24.2
NRIM 32.47
IOSP 68.67
MCRB 6.1
HABT 10.32
MRC 15.5
SWP 93.365
NVGS 9.49
TAN 22.31
CDAY 39.45
KALA 5.23
CKPT 3.595
VVR 4.075
CEA 30.85
AXTI 3.945
WSBC 41.48
DBX 23.47
HCFT 3.35
TD 55.96
GWRS 9.63
MGP 30.75
PIHPP 22.1
XHB 35.49
DDIV 22.74
CVM 2.79
LONE 4.8
GLO 9.03
HYAC 10.17
BOMN 24.94
BOKF 85.14
FWONK 30.81
MASI 121.78
IEF 103.97
AIG+ 7.06
ABEO 6.54
MCHI 57.725
VGSH 60.105
PCG-C 16.64
IXG 61.43
ANSS 160.61
PCOM 10.26
SCHM 52.62
QNST 18.16
IDXX 207.89
HIX 6.305
PHIOW 0.025
ETR 87.19
FCEF 20.36
GLUU 9.265
ATNI 72.9
PKG 92.17
TECD 94.68
F 8.605
LZB 29.19
XCEM 25.87
UNB 47.2
PBI 7.16
MDU 25.29
SAP 101.64
ROKU 43.99
DOGZ 3.67
HEB 0.2301
PBA 35.105
CLNY 5.87
FWONA 30.02
KR 28.22
SPNS 12.02
EEX 14.05
RBC 75.37
MFNC 15.8
PRE-G 25.82
LBC 9.49
OLN 23.9
MTG 12.28
CRF 11.675
HGV 30.255
MTSC 48.49
WSBF 16.69
IVOV 116.43
WDRW 30.87
CAMP 14.13
GBL 19.27
CAH 48.9
RPG 106.85
BTX 1.38
CLDX 0.3721
BSCM 20.78
SRAX 2.84
SAFE 17.28
BRO 26.75
TTP 15.03
GLIBA 44.1
RESN 3.28
VHI 3.24
UTI 3.52
BEL 24.89
CQQQ 43.47
BPMC 69.81
HEWJ 29.84
JAGG 25.34
AWK 93.77
MCFT 21.46
STBA 40.34
VYGR 10.46
GER 5.415
REG 64.8
FLIC 20.74
PUB 29.81
TANNL 24.35
HUSA 0.2001
