sample_out/46806838587281.txt
FMS 36.26
MTEC 10.14
JELD 16.62
FSZ 47.27
AMTD 55.52
RFP 9.13
YEXT 15.07
GMED 44.11
AUMN 0.337
ORMP 3.34
SFE 9.49
EVOP 25.05
TBBK 8.58
USCI 38.77
RBS 6.42
CTG 4.3
AFMD 3.19
DRIP 10.82
JTD 14.97
VYM 81.64
CBZ 19.6
ECA 6.925
SBFGP 18.22
SPEM 34.56
UNG 25.63
FII 26.53
WCC 53.38
EMX 1.14
ESL 121.45
BH.A 650.0
SDG 56.28
CTB 34.1
VET 24.19
VMI 126.46
IYJ 141.42
MBIO 3.35
VOX 78.38
XBIO 2.07
EMLP 23.35
DCP 33.97
MPAA 20.125
NVEC 93.05
JHSC 25.03
LMAT 23.84
RWM 42.59
ESNT 38.65
BGS 26.17
FICO 215.36
XELA 3.55
PERI 3.26
SPHD 40.67
TLC 6.5
HLIT 5.12
AMID 4.06
DK 32.43
VONV 103.53
HR 31.98
CACI 159.4
GNR 44.58
TBPH 24.69
DRW 30.72
WDAY 170.02
FENC 6.34
TRTN 35.54
CCLP 2.57
AYX 69.82
MDC 30.3
UJPY 25.3
CBRE 44.79
GPP 15.28
AGM 71.33
BLX 18.63
ISIG 1.18
CACG 28.715
CNDT 12.48
MNTX 6.98
VTC 81.25
DGS 45.12
IAGG 52.48
GLL 70.17
MSC 13.4
OGS 80.29
EPAM 139.355
CIGI 60.99
MXWL 3.0
KTF 10.89
AGO 40.26
AMBR 8.3
OIBR.C 1.64
FUV 3.03
CRS 44.535
BIOS 3.58
QSR 62.17
AMRWW 0.11
UFPI 29.13
PHB 18.28
IUSB 49.54
NOG 2.55
GWR 78.42
CPA 93.31
OPTN 6.11
SRE-B 99.87
ZF 9.2
FDEU 14.0
GLV 10.69
QTWO 57.55
AAON 35.52
SKIS 4.55
CPT 96.61
PII 83.46
BSIG 12.41
DHIL 155.84
FSK 6.35
HPE 15.45
ATIS 0.3052
REN 33.42
OZK 31.65
BTN 1.55
XLNX 111.34
GVAL 22.83
OLED 102.35
GSIT 7.76
PUMP 16.13
YINN 21.36
SCE-J 20.36
GNL-A 24.53
KMI 18.13
DG 114.9
SMDV 56.85
CPRT 49.75
QGEN 37.23
QARP 24.97
CLNC 16.26
WHLRP 10.25
RECN 16.6
GARS 7.39
CVA 15.71
URTH 84.01
USPH 106.74
ELF 8.38
ATHM 70.49
ERIC 8.875
CFFI 50.24
BPOPN 25.71
WVVI 7.06
MILN 21.66
VVV 22.44
BBRE 79.98
ANIP 53.7
XSW 82.92
RYTM 25.54
DIV 23.6
LMNR 21.65
NITE 12.92
PVTL 18.24
SPLV 48.91
CGIX 0.2432
ALNA 7.6
IMAX 20.84
DUK 85.75
RYB 7.14
CHEF 32.27
EEA 8.14
PSA-C 23.145
ARRS 31.28
CCS 21.71
BR 99.94
COHU 17.56
MGRC 49.57
ETJ 8.51
GXG 8.865
LECO 86.31
THM 0.6197
MDCA 2.94
CLIX 47.16
VDE 85.26
DPG 13.83
QYLD 21.75
ADSK 142.42
NYT 26.04
NSYS 4.18
PCG 13.57
VMW 146.43
PML 13.43
ORC 6.985
CBMB 12.78
CNS 37.13
CPE 8.17
FSCT 29.61
HSC 21.06
CNXM 17.45
FATE 14.03
LCNB 16.39
LXFT 57.7
FOXA 49.0
WEYS 27.11
EFR 13.07
WATT 7.25
HDSN 1.21
ALB 79.03
ELLI 72.8
GEN 1.5
WSC 10.09
NFRA 46.6
JXI 50.65
CIG 3.7
DLPN 1.42
FRT 131.36
LEO 7.63
ALDR 13.2
UCBI 26.17
MFA-B 24.77
AQN 10.89
DSM 7.33
FNLC 26.06
WMC 9.59
CASY 129.32
PCMI 21.25
MOBL 4.755
BSTC 64.35
SSRM 13.39
INSI 18.5
AUTO 3.09
CCR 18.45
GDO 15.98
RDVT 7.64
ON 19.73
SON 56.64
AAME 2.53
USO 11.495
CYH 3.72
CS 12.37
SNV 36.16
VTVT 2.72
QHC 3.05
PSAU 18.4
KIM-L 21.39
EPE 0.6808
HEES 26.08
ISSC 2.25
DEUS 30.62
EV 38.07
CLNY-J 20.31
WFC-Q 25.35
IBDQ 24.2
BIP 38.34
HALO 16.08
IPAR 66.53
TOWR 29.085
ADOM 0.252
IPLDP 24.9
CPST 0.8449
TNK 1.01
GRC 33.49
VOOV 104.61
PSCI 60.84
WHLM 5.85
WNEB 9.32
PFFA 23.805
KONA 1.11
AMAG 15.21
AUPH 6.34
YLCO 12.21
DAVA 23.97
CC 35.73
PDFS 10.21
TISA 0.52
AYTU 1.17
FINX 24.87
YVR 2.35
UIS 12.89
TMO 241.68
YRCW 5.81
UWN 2.47
TPH 12.455
VERU 1.48
WMB 26.92
XHE 74.61
COWNZ 24.92
MTEX 18.86
ETP-D 24.6
CSU 7.11
HLNE 36.14
DJP 22.6
OXY 66.63
BDC 52.47
FMHI 50.23
CDR-B 24.46
MSA 97.39
DGII 11.36
SAIC 67.52
PMBC 7.94
CIZ 31.45
UPWK 18.81
ARTX 3.49
KALV 17.34
BAX 71.29
CCD 19.32
PRO 33.9
STNLW 0.85
FELP 3.35
ERJ 20.79
DDWM 27.52
RZG 113.33
EMCB 69.57
NCTY 1.42
MMT 5.56
TIF 87.69
BMI 51.82
TOUR 4.39
SLNO 1.72
SBLKZ 25.04
CCMP 100.79
PSC 30.03
XRX 27.96
OMFL 26.45
VLGEA 26.58
DBP 37.16
LTPZ 62.57
XHR 18.58
ATHN 134.54
FOE 16.455
CURE 51.2
FPAY 0.799
DRAD 0.7
JMEI 2.575
TNXP 1.99
DRRX 0.5908
SSW-H 23.25
NIU 7.61
FTXD 21.54
BRSS 29.37
OSG 1.885
MGLN 66.25
XLU 53.37
NPTN 6.985
DNLI 18.67
DAIO 5.84
HYLB 48.675
REGL 54.69
IDEV 52.04
UMBF 63.36
SLYG 58.0
GRNQ 3.2
PPT 4.97
CHY 10.945
NOA 10.35
RWW 63.03
LENS 0.425
MDYV 49.21
DLS 64.32
NESR 7.86
HTLD 20.21
KNL 19.61
JLL 140.02
SBFG 18.4
NAVG 69.75
GSLC 53.49
KBE 43.06
C-N 26.27
RFEU 56.47
CRL 121.93
JILL 6.01
OHGI 0.1219
PHT 8.5
MXL 19.12
CERS 5.73
GLMD 7.45
DVD 1.99
CBD 26.09
HIL 3.33
EMO 9.62
HST 18.145
DVN 27.29
SPXU 38.38
AIMC 29.47
TRT 2.95
NEE 172.945
EOLS 15.19
FAN 12.58
CENX 8.73
RUBY 13.62
EDD 6.64
VHT 166.82
TNC 58.4
SALM 2.77
CHAP 7.95
LXFR 19.9
ORLY 343.95
RGR 53.35
WGP 32.9
APO-A 24.52
DES 26.97
WSTL 2.25
GFI 3.985
EES 35.57
ALD 44.03
AMN 64.39
NEO 16.7
BDC-B 72.19
ALDX 8.37
WOR 36.77
TWOU 55.9
PFL 11.29
AGCO 63.54
MGA 52.1
BKK 14.93
CEI 0.461
EPHE 34.22
AVAL 6.8
DWSH 25.9
AFIF 9.94
BPFH 11.7
ACRE 14.39
IYH 187.34
TEL 79.21
PRCP 8.13
DRN 22.55
SPOK 13.66
EDV 112.52
BWA 40.34
PAHC 31.11
SCOR 19.2
EOT 20.83
EXFO 3.28
VRSK 117.05
FLR 35.94
ALLT 6.74
EPR 72.57
HTY 6.9
CBH 8.76
ICLR 137.81
RFDI 55.35
TECS 22.49
CABO 866.6
MYJ 13.53
SPB 54.28
UAL 86.87
PRTA 11.71
SCHZ 50.83
LYV 52.73
AFSI-C 8.05
NPV 12.04
ARNC 18.595
VSEC 31.79
AME 71.84
KMT 37.63
PRTO 2.6
JG 7.71
BAH 48.37
MOXC 0.5201
MTUM 104.96
REGI 28.11
GLTR 64.92
FULT 16.26
PSJ 80.79
NUV 9.615
CI 198.73
ANH 4.49
ACER 23.71
CYTR 0.555
ATSG 23.38
JKE 169.29
ENB 36.5
IPHS 29.95
VIXM 24.26
FLWS 13.18
COPX 19.79
C-K 26.73
IESC 16.61
ATISW 0.08
APDN 0.441
VRTS 85.67
TCGP 22.49
SPXC 29.06
EVFM 3.44
INDL 58.5
DTV 53.3
PYPL 92.1
DCOM 19.64
EVA 30.11
FCBP 21.435
TDE 24.99
GRA 71.07
EPC 38.875
JAKK 1.8
ASTC 5.05
BSE 12.45
UG 19.44
DATA 126.36
FN 54.66
COUP 79.3
CTRN 20.61
DOG 57.41
ERF 8.84
ENT 2.62
GSBD 20.285
PDEX 14.705
FOLD 11.22
JAZZ 125.38
TRTX 19.54
SFST 37.09
TDW+A 2.22
BSCE 25.15
PZD 40.03
FTFT 0.79
ZG 32.7
SCO 20.165
HOFT 28.05
KGJI 0.77
SPWR 5.66
NRT 6.25
SOLOW 0.4
KOP 23.03
KRC 70.53
TOTL 47.48
JDST 41.84
IGOV 48.91
CVLY 22.0
TTS 7.47
WBC 112.37
COWN 15.57
FTSV 14.41
MITT 17.865
RWR 95.28
CHMG 42.24
GASL 8.23
RJI 5.24
TENB 26.91
AIHS 4.0
MSI 116.48
WBIG 23.34
MARPS 2.0
IPG 22.71
JPI 21.83
MSCI 161.95
RNR 139.81
ETON 6.2
FEX 56.33
MS-K 25.44
PLND 17.14
HSDT 7.31
MLM 178.97
SRV 9.88
TRI 51.58
STND 31.2
HUBG 44.21
EDRY 7.66
LLL 197.74
IYF 115.78
EXTR 7.535
CORT 11.64
NSP 104.66
GLP 19.24
CHSCP 28.97
BGIO 8.72
ENOB 6.01
HL 2.565
PHCF 5.0
DFFN 2.16
SEND 49.2
CCOI 46.84
MIDU 36.46
KNX 33.13
TAIT 2.0
MODN 14.28
KMB 108.26
HYHG 65.07
APM 12.88
OKTA 78.3
HYLS 46.79
ARTNA 34.35
IGSB 52.09
NULG 32.16
FIF 14.96
LOGI 35.85
RETA 75.3
ECOL 62.62
MPB 23.99
CTL 14.915
ALTY 14.46
NAII 11.04
MBOT 8.55
FDUSL 25.3
TVTY 21.905
BFR 13.45
ATOM 3.94
NOC 280.29
VTSI 3.99
SBUX 67.76
FMAO 31.11
MITT-B 25.315
FET 4.92
EWH 24.3
NTRS 89.02
SDIV 19.035
SONO 11.2
CHN 18.86
VLRS 7.39
SLY 65.3
STL 19.4
AGYS 17.88
FAM 9.85
NCLH 50.18
ULH 20.26
ALG 86.27
NNVC 0.31
THRM 40.68
BAF 13.28
UTSL 26.95
BH 128.65
EDZ 47.29
GLW 33.36
WWE 82.11
MORT 23.06
TRK 15.93
SRC 39.07
FCNCA 410.54
BHK 12.92
TRGP 43.42
SBNY 126.65
CWK 16.37
ET 14.72
TYD 42.81
EARS 0.431
FREL 24.75
FNY 40.18
SMMF 23.11
SPG 181.82
SNN 37.73
RHI 65.61
NBN 20.02
SSNC 50.16
CNP-B 52.76
THFF 41.48
IYR 82.66
COR 97.45
INFU 3.75
NGVC 13.33
NEWTI 25.58
AGRX 0.8304
BB 8.025
FSM 3.82
VGZ 0.66
HWKN 41.5
SNBR 35.31
PB 72.13
AOS 47.0
SRTY 29.49
MOSY 0.1799
IBDR 23.55
VRRM 10.26
IAI 60.57
OPNT 14.7
LUV 57.35
POOL 150.4
APPN 31.54
REV 24.78
EYES 0.83
AEO 21.17
MEIP 2.695
CFBI 10.68
TYME 2.75
NOMD 17.95
NWE 62.5
BIF 10.61
DPST 47.2
BHVN 38.97
ROAN 10.9
DFS 67.31
BCS 8.44
KSA 32.01
PSA-E 22.17
OSMT 7.92
MYE 16.04
LOGC 8.54
AMRX 12.03
SELF 4.0
AGR 48.96
GMLP 13.13
SLIM 32.5
BOCH 11.13
OPINI 23.75
NRIM 33.0
IOSP 68.52
MCRB 6.07
HABT 10.35
MRC 15.49
SWP 94.11
NVGS 9.48
TAN 22.37
CDAY 39.59
KALA 5.24
CKPT 3.64
VVR 4.085
CEA 30.85
AXTI 3.99
WSBC 41.36
FRC-D 24.04
DBX 23.605
HCFT 3.37
TD 55.84
GWRS 9.63
MGP 30.85
PIHPP 22.1
XHB 35.51
DDIV 22.74
CVM 2.88
LONE 4.82
GLO 9.08
PFI 31.08
HYAC 10.17
BOMN 24.94
BOKF 85.05
FWONK 30.78
MASI 122.03
IEF 104.02
AIG+ 7.03
ABEO 6.56
MCHI 57.83
VGSH 60.105
PCG-C 16.64
IXG 61.43
ANSS 160.51
PCOM 10.29
SCHM 52.65
QNST 18.38
IDXX 207.1
HIX 6.305
PHIOW 0.025
ETR 86.85
FCEF 20.36
GLUU 9.365
PKG 92.03
TECD 94.58
F 8.58
LZB 29.16
XCEM 25.87
UNB 47.2
PBI 7.14
MDU 25.32
SAP 101.56
ROKU 43.68
DOGZ 3.67
HEB 0.2321
PBA 35.21
CLNY 5.855
FWONA 30.02
KR 28.23
SPNS 12.02
EEX 14.0
RBC 75.37
MFNC 15.8
PRE-G 25.82
LBC 9.49
OLN 23.76
MTG 12.27
CRF 11.675
HGV 30.39
MTSC 48.63
WSBF 16.66
IVOV 116.43
WDRW 30.59
CAMP 14.08
GBL 19.27
CAH 48.58
RPG 107.25
BTX 1.375
CLDX 0.3881
